<?xml version="1.0"?>
<robot name="agv" xmlns:xacro="http://www.ros.org/wiki/xacro">

    <xacro:macro name="cylinder_inertia" params="m r h">
        <inertia ixx="${m*(3*r*r+h*h)/12}" ixy = "0" ixz = "0"
                 iyy="${m*(3*r*r+h*h)/12}" iyz = "0"
                 izz="${m*r*r/2}"/> 
    </xacro:macro>

    <xacro:macro name="box_inertia" params="m l w h">
        <inertia ixx="${m*(h*h+l*l)/12}" ixy = "0" ixz = "0"
                 iyy="${m*(w*w+h*h)/12}" iyz = "0"
                 izz="${m*(w*w+l*l)/12}" /> 
    </xacro:macro>

    <xacro:macro name="sphere_inertia" params="m r">
        <inertia ixx="${2*m*r*r/5}" ixy = "0" ixz = "0"
                 iyy="${2*m*r*r/5}" iyz = "0"
                 izz="${2*m*r*r/5}" /> 
    </xacro:macro>

    <xacro:macro name="chassis" params="name length width height *origin *material">
        <visual>
            <xacro:insert_block name="origin"/>            
            <geometry>
                <box size ="${length} ${width} ${height}"/>
            </geometry>
            <xacro:insert_block name="material"/>
        </visual>
    </xacro:macro>

    <xacro:macro name="wheel" params="name *origin">
        <link name="wheel_${name}_link">
            <inertial>
                <origin xyz="0.0 0.0 0.0" rpy="${PI/2} 0.0 0.0"/>
                <mass value="${wheel_mass}"/>
                <xacro:cylinder_inertia m="${wheel_mass}" r="${wheel_radius}" h="${wheel_width}"/>
            </inertial>
            
            <visual>
                <origin xyz="0.0 0.0 0.0" rpy="${PI/2} 0.0 0.0"/>
                <geometry>
                    <cylinder radius="${wheel_radius}" length="${wheel_width}"/>
                </geometry>
                <material name="black"/>
            </visual>

            <collision>
                <origin xyz="0.0 0.0 0.0" rpy="${PI/2} 0.0 0.0"/>
                <geometry>
                    <cylinder radius="${wheel_radius}" length="${wheel_width}"/>
                </geometry>
            </collision>
        </link>

        <joint name="wheel_${name}_joint" type="continuous">
            <parent link="base_link"/>
            <child link="wheel_${name}_link"/>
            <axis xyz="0 1 0"/>
            <xacro:insert_block name="origin"/>
        </joint>
    </xacro:macro>

</robot>